# Translations template for PROJECT.
# Copyright (C) 2018 ORGANIZATION
# This file is distributed under the same license as the PROJECT project.
# FIRST AUTHOR <EMAIL@ADDRESS>, 2018.
#
#, fuzzy
msgid ""
msgstr ""
"Project-Id-Version: PROJECT VERSION\n"
"Report-Msgid-Bugs-To: EMAIL@ADDRESS\n"
"POT-Creation-Date: 2018-12-28 00:31+0800\n"
"PO-Revision-Date: YEAR-MO-DA HO:MI+ZONE\n"
"Last-Translator: FULL NAME <EMAIL@ADDRESS>\n"
"Language-Team: LANGUAGE <LL@li.org>\n"
"MIME-Version: 1.0\n"
"Content-Type: text/plain; charset=utf-8\n"
"Content-Transfer-Encoding: 8bit\n"
"Generated-By: Babel 2.5.1\n"

#: apps/modules/audit/process/rules.py:41
msgid "rule"
msgstr ""

#: apps/modules/audit/process/rules.py:47
msgid "The rule already exists"
msgstr ""

#: apps/modules/audit/process/rules.py:53
#: apps/modules/category/process/category.py:74
#: apps/modules/permission/process/permission.py:78
#: apps/modules/user/process/role.py:45
msgid "Add a success"
msgstr ""

#: apps/modules/audit/process/rules.py:67
#: apps/modules/category/process/category.py:124
msgid "Delete the success,{}"
msgstr ""

#: apps/modules/audit/process/rules.py:70
#: apps/modules/category/process/category.py:127
#: apps/modules/comments/process/comment.py:233
#: apps/modules/permission/process/url_permission.py:192
msgid "Delete failed"
msgstr ""

#: apps/modules/category/process/category.py:23
msgid "category id"
msgstr ""

#: apps/modules/category/process/category.py:43
#: apps/modules/category/process/category.py:59
msgid "category type"
msgstr ""

#: apps/modules/category/process/category.py:64
#: apps/modules/category/process/category.py:86
#: apps/modules/media/process/media.py:55
#: apps/modules/media/process/media.py:213
#: apps/modules/permission/process/permission.py:80
#: apps/modules/permission/process/permission.py:123
#: apps/modules/plug_in_manager/process/manager.py:52
#: apps/modules/plug_in_manager/process/manager.py:88
#: apps/modules/plug_in_manager/process/manager.py:112
#: apps/modules/theme_setting/process/display_setting.py:53
#: apps/modules/theme_setting/process/display_setting.py:205
#: apps/modules/user/process/role.py:51 apps/modules/user/process/role.py:54
#: apps/modules/user/process/role.py:95
msgid "name"
msgstr ""

#: apps/modules/category/process/category.py:71
#: apps/modules/category/process/category.py:93
msgid "Name already exists"
msgstr ""

#: apps/modules/category/process/category.py:99
#: apps/modules/media/process/media.py:293
#: apps/modules/permission/process/url_permission.py:167
#: apps/modules/plug_in_manager/process/setting.py:142
#: apps/modules/setting/process/settings.py:248
#: apps/modules/theme_setting/process/display_setting.py:286
msgid "Modify the success"
msgstr ""

#: apps/modules/category/process/category.py:101
#: apps/modules/permission/process/url_permission.py:169
msgid "No modification"
msgstr ""

#: apps/modules/comments/process/adm_comment.py:44
msgid "Comment on alleged violations"
msgstr ""

#: apps/modules/comments/process/adm_comment.py:70
#: apps/modules/post/process/adm_post.py:71
msgid "Submitted successfully, {}"
msgstr ""

#: apps/modules/comments/process/adm_comment.py:73
#: apps/modules/post/process/adm_post.py:74
msgid "Submitted failed"
msgstr ""

#: apps/modules/comments/process/adm_comment.py:86
#: apps/modules/post/process/adm_post.py:88
msgid "Move to a permanently deleted area, {}"
msgstr ""

#: apps/modules/comments/process/adm_comment.py:89
msgid "Does not match the data to be deleted"
msgstr ""

#: apps/modules/comments/process/adm_comment.py:96
#: apps/modules/post/process/post_process.py:279
msgid "Removed from the database, {}"
msgstr ""

#: apps/modules/comments/process/adm_comment.py:99
#: apps/modules/comments/process/adm_comment.py:114
#: apps/modules/post/process/adm_post.py:91
#: apps/modules/post/process/adm_post.py:107
#: apps/modules/post/process/post_process.py:282
#: apps/modules/post/process/user_post.py:200
msgid "No match to relevant data"
msgstr ""

#: apps/modules/comments/process/adm_comment.py:111
#: apps/modules/post/process/adm_post.py:104
msgid "Restore success, {}"
msgstr ""

#: apps/modules/comments/process/comment.py:38
msgid "Comment feature is not open"
msgstr ""

#: apps/modules/comments/process/comment.py:49
msgid "comment"
msgstr ""

#: apps/modules/comments/process/comment.py:65
msgid "You comment too often and come back later"
msgstr ""

#: apps/modules/comments/process/comment.py:74
msgid "Articles do not exist or have not been published"
msgstr ""

#: apps/modules/comments/process/comment.py:82
msgid "Your comment goal does not exist"
msgstr ""

#: apps/modules/comments/process/comment.py:107
msgid "Guest reviews feature is not open, please login account comments"
msgstr ""

#: apps/modules/comments/process/comment.py:165
msgid "[Label:{}]Comment on alleged violations"
msgstr ""

#: apps/modules/comments/process/comment.py:193
msgid "Successful reviews"
msgstr ""

#: apps/modules/comments/process/comment.py:231
#: apps/modules/post/process/user_post.py:191
msgid "Delete the success"
msgstr ""

#: apps/modules/comments/process/comment.py:265
#: apps/modules/post/process/post.py:86
msgid "Success"
msgstr ""

#: apps/modules/comments/process/comment.py:267
#: apps/modules/post/process/post.py:88
msgid "Failed"
msgstr ""

#: apps/modules/comments/process/comment_find.py:17
#: apps/modules/post/process/post_process.py:38
msgid "The \"pre\" must not exceed the maximum amount"
msgstr ""

#: apps/modules/content_inform/process/inform.py:38
msgid "details"
msgstr ""

#: apps/modules/content_inform/process/inform.py:61
msgid "Submitted successfully, thanks for your participation"
msgstr ""

#: apps/modules/content_inform/process/inform.py:64
msgid "Submit failed, please try again"
msgstr ""

#: apps/modules/follow/process/user_follow.py:42
msgid "Followed"
msgstr ""

#: apps/modules/follow/process/user_follow.py:45
msgid "You can't follow yourself"
msgstr ""

#: apps/modules/follow/process/user_follow.py:48
msgid "You are already following this user"
msgstr ""

#: apps/modules/follow/process/user_follow.py:83
msgid "Unfollow success"
msgstr ""

#: apps/modules/follow/process/user_follow.py:86
msgid "Unfollow failed"
msgstr ""

#: apps/modules/global_data/process/global_data.py:44
msgid "Get the current user information successfully"
msgstr ""

#: apps/modules/media/process/media.py:51
#: apps/modules/media/process/media.py:155
#: apps/modules/theme_setting/process/display_setting.py:49
#: apps/modules/theme_setting/process/display_setting.py:151
msgid "type"
msgstr ""

#: apps/modules/media/process/media.py:71
#: apps/modules/media/process/media.py:262
#: apps/modules/theme_setting/process/display_setting.py:69
#: apps/modules/theme_setting/process/display_setting.py:255
msgid "The type \"{}\" exists in the name \"{}\""
msgstr ""

#: apps/modules/media/process/media.py:104
#: apps/modules/theme_setting/process/display_setting.py:102
msgid "{} uploaded successfully"
msgstr ""

#: apps/modules/media/process/media.py:109
#: apps/modules/permission/process/url_permission.py:108
#: apps/modules/theme_setting/process/display_setting.py:107
#: apps/modules/theme_setting/process/page.py:68
msgid "Added successfully"
msgstr ""

#: apps/modules/media/process/media.py:234
#: apps/modules/theme_setting/process/display_setting.py:227
msgid "Update picture successfully"
msgstr ""

#: apps/modules/media/process/media.py:236
#: apps/modules/theme_setting/process/display_setting.py:229
msgid "Failed to update"
msgstr ""

#: apps/modules/media/process/media.py:295
#: apps/modules/theme_setting/process/display_setting.py:288
msgid "The content is not modified"
msgstr ""

#: apps/modules/media/process/media.py:320
#: apps/modules/theme_setting/process/display_setting.py:311
msgid "{} files have been deleted"
msgstr ""

#: apps/modules/media/process/media.py:322
#: apps/modules/message/process/sys_message.py:88
#: apps/modules/message/process/user_message.py:186
#: apps/modules/plug_in_manager/process/manager.py:124
#: apps/modules/setting/process/host_setting.py:70
#: apps/modules/theme_setting/process/display_setting.py:313
msgid "Failed to delete"
msgstr ""

#: apps/modules/message/process/send_msg.py:31
#: apps/modules/post/process/user_post.py:55
msgid "title"
msgstr ""

#: apps/modules/message/process/send_msg.py:32
#: apps/modules/post/process/user_post.py:60
#: apps/modules/post/process/user_post.py:69
msgid "content"
msgstr ""

#: apps/modules/message/process/send_msg.py:33
msgid "send type"
msgstr ""

#: apps/modules/message/process/send_msg.py:34
msgid "user name"
msgstr ""

#: apps/modules/message/process/send_msg.py:69
msgid "Station news success"
msgstr ""

#: apps/modules/message/process/send_msg.py:71
msgid "No relevant user"
msgstr ""

#: apps/modules/message/process/send_msg.py:82
msgid "Mail message is being sent"
msgstr ""

#: apps/modules/message/process/send_msg.py:84
msgid "There is no such email address user"
msgstr ""

#: apps/modules/message/process/send_msg.py:97
msgid "SMS sent"
msgstr ""

#: apps/modules/message/process/send_msg.py:99
msgid "No user mobile phone number was obtained"
msgstr ""

#: apps/modules/message/process/sys_message.py:86
#: apps/modules/message/process/user_message.py:184
#: apps/modules/permission/process/permission.py:185
#: apps/modules/permission/process/url_permission.py:190
#: apps/modules/plug_in_manager/process/manager.py:118
#: apps/modules/theme_setting/process/page.py:101
#: apps/modules/theme_setting/process/themes.py:268
msgid "Successfully deleted"
msgstr ""

#: apps/modules/message/process/user_message.py:160
#: apps/modules/user/process/profile.py:100
msgid "Update succeed"
msgstr ""

#: apps/modules/message/process/user_message.py:162
#: apps/modules/permission/process/permission.py:164
#: apps/modules/setting/process/host_setting.py:57
#: apps/modules/user/process/adm_user.py:122
#: apps/modules/user/process/profile.py:102
#: apps/modules/user/process/profile.py:154
#: apps/modules/user/process/role.py:124 apps/modules/user/process/role.py:130
msgid "No changes"
msgstr ""

#: apps/modules/permission/process/permission.py:27
msgid "The specified permission is not found"
msgstr ""

#: apps/modules/permission/process/permission.py:80
#: apps/modules/permission/process/permission.py:123
msgid "position"
msgstr ""

#: apps/modules/permission/process/permission.py:89
#: apps/modules/permission/process/permission.py:131
msgid "Must be an integer greater than 0, less than or equal to {}"
msgstr ""

#: apps/modules/permission/process/permission.py:93
msgid "Permission name or valready exists"
msgstr ""

#: apps/modules/permission/process/permission.py:97
#: apps/modules/permission/process/permission.py:157
msgid "Location has been used"
msgstr ""

#: apps/modules/permission/process/permission.py:102
#: apps/modules/user/process/role.py:59
msgid ""
"The current user permissions are lower than the permissions that you want"
" to add, without permission to add"
msgstr ""

#: apps/modules/permission/process/permission.py:135
#: apps/modules/permission/process/url_permission.py:142
#: apps/modules/user/process/role.py:99
msgid ""
"The current user permissions are lower than the permissions you want to "
"modify, without permission to modify"
msgstr ""

#: apps/modules/permission/process/permission.py:151
#: apps/modules/post/process/user_post.py:177
#: apps/modules/user/process/role.py:118
msgid "Save success"
msgstr ""

#: apps/modules/permission/process/permission.py:153
msgid "Permission name already exists"
msgstr ""

#: apps/modules/permission/process/permission.py:188
msgid "Successfully deleted, and {} have no permission to delete"
msgstr ""

#: apps/modules/permission/process/url_permission.py:36
msgid "No relevant data found"
msgstr ""

#: apps/modules/permission/process/url_permission.py:93
#: apps/modules/theme_setting/process/page.py:32
msgid "routing"
msgstr ""

#: apps/modules/permission/process/url_permission.py:98
msgid "Routing already exists"
msgstr ""

#: apps/modules/permission/process/url_permission.py:111
msgid "Add failed"
msgstr ""

#: apps/modules/permission/process/url_permission.py:128
msgid "method"
msgstr ""

#: apps/modules/plug_in_manager/process/manager.py:61
msgid "Plugin[{}] with similar functionality is in use, please stop it first"
msgstr ""

#: apps/modules/plug_in_manager/process/manager.py:73
msgid "Plug-in activated successfully"
msgstr ""

#: apps/modules/plug_in_manager/process/manager.py:75
msgid "Plug-in is already activated"
msgstr ""

#: apps/modules/plug_in_manager/process/manager.py:77
msgid "Plug-in activation failed"
msgstr ""

#: apps/modules/plug_in_manager/process/manager.py:98
msgid "Plug-in stopped successfully"
msgstr ""

#: apps/modules/plug_in_manager/process/manager.py:100
msgid "Plug-in failed to stop"
msgstr ""

#: apps/modules/plug_in_manager/process/manager.py:139
#: apps/modules/theme_setting/process/themes.py:99
msgid "File format error, please upload zip archive"
msgstr ""

#: apps/modules/plug_in_manager/process/manager.py:150
msgid "The same name plugin already exists"
msgstr ""

#: apps/modules/plug_in_manager/process/manager.py:168
#: apps/modules/theme_setting/process/themes.py:108
#: apps/modules/theme_setting/process/themes.py:123
msgid "The same name theme already exists"
msgstr ""

#: apps/modules/plug_in_manager/process/setting.py:44
#: apps/modules/setting/process/host_setting.py:27
#: apps/modules/setting/process/settings.py:129
msgid ""
"The KEY_HIDING switch in the system configuration has been enabled. The "
"value of the password type has been replaced."
msgstr ""

#: apps/modules/plug_in_manager/process/setting.py:75
#: apps/modules/setting/process/settings.py:132
#: apps/modules/setting/process/settings.py:151
msgid "There is no such data"
msgstr ""

#: apps/modules/plug_in_manager/process/setting.py:112
#: apps/modules/plug_in_manager/process/setting.py:119
#: apps/modules/plug_in_manager/process/setting.py:129
#: apps/modules/setting/process/settings.py:188
#: apps/modules/setting/process/settings.py:195
#: apps/modules/setting/process/settings.py:205
msgid "The format of the \"value\" errors, need a \"{}\" type"
msgstr ""

#: apps/modules/plug_in_manager/process/setting.py:125
#: apps/modules/setting/process/settings.py:201
msgid "There is no {}"
msgstr ""

#: apps/modules/plug_in_manager/process/setting.py:164
msgid "Refreshed successfully"
msgstr ""

#: apps/modules/plug_in_manager/process/setting.py:166
msgid ""
"Failed to refresh. Please check the previous plug-in page for error "
"messages"
msgstr ""

#: apps/modules/plug_in_manager/process/setting.py:184
msgid "There is no requirement file"
msgstr ""

#: apps/modules/plug_in_manager/process/setting.py:244
msgid ""
"Some host connections failed. Successfully connected host has installed "
"requirements package in the background"
msgstr ""

#: apps/modules/plug_in_manager/process/setting.py:248
msgid "Executed related installation commands in the background"
msgstr ""

#: apps/modules/post/process/adm_post.py:67
msgid "Post allegedly violated"
msgstr ""

#: apps/modules/post/process/user_post.py:37
msgid "Up to {} tags are used"
msgstr ""

#: apps/modules/post/process/user_post.py:44
msgid "tag"
msgstr ""

#: apps/modules/post/process/user_post.py:172
msgid "[Label:{}]Post allegedly violated"
msgstr ""

#: apps/modules/post/process/user_post.py:175
msgid "Issue success"
msgstr ""

#: apps/modules/post/process/user_post.py:188
msgid "Removed to recycle bin"
msgstr ""

#: apps/modules/post/process/user_post.py:197
msgid "{},{}"
msgstr ""

#: apps/modules/post/process/user_post.py:215
msgid "Restore success,{}"
msgstr ""

#: apps/modules/post/process/user_post.py:218
msgid "Restore failed"
msgstr ""

#: apps/modules/search/process/search.py:26
msgid "keyword"
msgstr ""

#: apps/modules/setting/process/get_file_log.py:29
#: apps/modules/setting/process/host_setting.py:94
msgid "Connection host[{}] failed,Check the host Settings"
msgstr ""

#: apps/modules/setting/process/get_file_log.py:69
#: apps/modules/setting/process/host_setting.py:118
msgid "There is no host {}"
msgstr ""

#: apps/modules/setting/process/host_setting.py:40
#: apps/modules/user/process/profile.py:114
msgid "username"
msgstr ""

#: apps/modules/setting/process/host_setting.py:40
msgid "password"
msgstr ""

#: apps/modules/setting/process/host_setting.py:55
msgid "The update is successful"
msgstr ""

#: apps/modules/setting/process/host_setting.py:67
msgid "Successfully deleted {} host information"
msgstr ""

#: apps/modules/setting/process/host_setting.py:89
#: apps/modules/setting/process/host_setting.py:139
msgid "[{}] {}"
msgstr ""

#: apps/modules/setting/process/host_setting.py:107
msgid "[Warning]: \"sudo\" command go to the server"
msgstr ""

#: apps/modules/setting/process/host_setting.py:109
msgid "[Warning]: \"rm\" command go to the server"
msgstr ""

#: apps/modules/setting/process/host_setting.py:114
msgid "Command executed {}"
msgstr ""

#: apps/modules/setting/process/host_setting.py:143
msgid "Connection host[{}] failed"
msgstr ""

#: apps/modules/setting/process/host_setting.py:147
msgid "Successfully connecting server host"
msgstr ""

#: apps/modules/setting/process/host_setting.py:149
msgid "Host does not exist"
msgstr ""

#: apps/modules/setting/process/session_set.py:20
msgid "Set up language success"
msgstr ""

#: apps/modules/setting/process/session_set.py:22
msgid "Does not support this language"
msgstr ""

#: apps/modules/setting/process/settings.py:37
msgid "Lack of parameter"
msgstr ""

#: apps/modules/setting/process/settings.py:54
#: apps/modules/setting/process/settings.py:60
#: apps/modules/theme_setting/process/themes.py:210
msgid "Switch success"
msgstr ""

#: apps/modules/theme_setting/process/page.py:22
msgid "file type"
msgstr ""

#: apps/modules/theme_setting/process/page.py:36
#: apps/modules/theme_setting/process/page.py:46
msgid "This route can not be used"
msgstr ""

#: apps/modules/theme_setting/process/page.py:53
msgid "Routing existing"
msgstr ""

#: apps/modules/theme_setting/process/page.py:89
#: apps/modules/theme_setting/process/static_file.py:93
msgid "File not found,'{}'"
msgstr ""

#: apps/modules/theme_setting/process/page.py:104
msgid "This file can not be deleted"
msgstr ""

#: apps/modules/theme_setting/process/static_file.py:116
msgid "File does not exist can not be edited,'{}'"
msgstr ""

#: apps/modules/theme_setting/process/static_file.py:122
msgid "Saved successfully"
msgstr ""

#: apps/modules/theme_setting/process/themes.py:31
msgid "Get success"
msgstr ""

#: apps/modules/theme_setting/process/themes.py:34
msgid "Readme file does not exist"
msgstr ""

#: apps/modules/theme_setting/process/themes.py:151
msgid "Theme installed successfully"
msgstr ""

#: apps/modules/theme_setting/process/themes.py:173
msgid "Configuration file \"conf.yaml\" but few parameters \"{}\""
msgstr ""

#: apps/modules/theme_setting/process/themes.py:177
msgid ""
"The theme name and theme directory name in the configuration are "
"inconsistent.(\"{}\" compared with \"{}\")"
msgstr ""

#: apps/modules/theme_setting/process/themes.py:180
msgid ""
"The theme of the upload is incorrect, the configuration file(conf.yaml) "
"does not exist"
msgstr ""

#: apps/modules/theme_setting/process/themes.py:193
#: apps/modules/theme_setting/process/themes.py:226
msgid "Theme does not exist"
msgstr ""

#: apps/modules/theme_setting/process/themes.py:228
msgid "The current use of the theme can not be deleted"
msgstr ""

#: apps/modules/theme_setting/process/themes.py:239
msgid "Delete failed, at least keep a theme"
msgstr ""

#: apps/modules/token/process/rest_token.py:26
msgid "Created successfully"
msgstr ""

#: apps/modules/upload/process/upload_file.py:49
msgid "Uploaded successfully"
msgstr ""

#: apps/modules/upload/process/upload_file.py:56
#: apps/modules/user/process/avatar_upload.py:77
msgid "Upload failed"
msgstr ""

#: apps/modules/upload/process/upload_file.py:63
#: apps/modules/upload/process/upload_file.py:67
msgid "Get file error"
msgstr ""

#: apps/modules/upload/process/upload_file.py:70
msgid "No file submitted"
msgstr ""

#: apps/modules/user/apis/inspection_query.py:32
msgid "This {} address has been registered"
msgstr ""

#: apps/modules/user/apis/inspection_query.py:35
#: apps/modules/user/process/email.py:31
msgid "This is the email address you currently use"
msgstr ""

#: apps/modules/user/apis/inspection_query.py:38
msgid "This {} can be used"
msgstr ""

#: apps/modules/user/apis/inspection_query.py:53
#: apps/modules/user/apis/inspection_query.py:56
msgid "The ID belongs to the current logged in user"
msgstr ""

#: apps/modules/user/apis/online.py:109 apps/modules/user/apis/online.py:116
msgid "Successfully logged out"
msgstr ""

#: apps/modules/user/process/adm_user.py:22
#: apps/modules/user/process/user_profile_process.py:31
#: apps/modules/user/process/user_profile_process.py:58
msgid "The specified user is not found"
msgstr ""

#: apps/modules/user/process/adm_user.py:102
#: apps/modules/user/process/profile.py:157
msgid "Update success"
msgstr ""

#: apps/modules/user/process/adm_user.py:116
msgid "No permission modification"
msgstr ""

#: apps/modules/user/process/adm_user.py:152
msgid "Has recovered {} users, {} users can not operate"
msgstr ""

#: apps/modules/user/process/adm_user.py:155
msgid "Recycle user failed.May not have permission"
msgstr ""

#: apps/modules/user/process/adm_user.py:161
msgid "{} users have been deleted and {} users can not be deleted"
msgstr ""

#: apps/modules/user/process/adm_user.py:164
msgid "Failed to delete.May not have permission"
msgstr ""

#: apps/modules/user/process/adm_user.py:191
msgid "Restore the {} users,The other {} users have no power control"
msgstr ""

#: apps/modules/user/process/adm_user.py:194
msgid "Restore the failure.May not have permission"
msgstr ""

#: apps/modules/user/process/adm_user.py:221
msgid "{} user activation is successful, {} no permission to operate"
msgstr ""

#: apps/modules/user/process/adm_user.py:224
msgid "Activation failed.May not have permission"
msgstr ""

#: apps/modules/user/process/avatar_upload.py:31
#: apps/modules/user/process/avatar_upload.py:39
msgid "Upload avatar image can not exceed {}M"
msgstr ""

#: apps/modules/user/process/avatar_upload.py:67
msgid "Save failed"
msgstr ""

#: apps/modules/user/process/avatar_upload.py:75
msgid "Save successfully"
msgstr ""

#: apps/modules/user/process/email.py:22
msgid "email"
msgstr ""

#: apps/modules/user/process/email.py:27
msgid "This E-mail address has been registered"
msgstr ""

#: apps/modules/user/process/email.py:40
msgid "Invalid verification code [currently bound]"
msgstr ""

#: apps/modules/user/process/email.py:43
msgid "Invalid verification code [ready to bind]"
msgstr ""

#: apps/modules/user/process/email.py:72
msgid "Verification code error [currently bound]"
msgstr ""

#: apps/modules/user/process/email.py:87
msgid "Verification code error [ready to bind]"
msgstr ""

#: apps/modules/user/process/email.py:102
msgid "Email is changed"
msgstr ""

#: apps/modules/user/process/email.py:112
msgid "Password mistake"
msgstr ""

#: apps/modules/user/process/online.py:13
msgid "Sorry, temporarily unregistered function"
msgstr ""

#: apps/modules/user/process/online.py:39
msgid "remember_me requires an integer"
msgstr ""

#: apps/modules/user/process/password.py:22
#: apps/modules/user/process/password.py:89
msgid "Now use the password mistake"
msgstr ""

#: apps/modules/user/process/password.py:25
#: apps/modules/user/process/password.py:131
msgid "Two password is not the same"
msgstr ""

#: apps/modules/user/process/password.py:77
msgid "Password change is successful, please login again"
msgstr ""

#: apps/modules/user/process/password.py:84
msgid "Password change failed(unknown error)"
msgstr ""

#: apps/modules/user/process/password.py:105
#: apps/modules/user/process/password.py:118
msgid "Account does not exist"
msgstr ""

#: apps/modules/user/process/password.py:122
msgid "Email or SMS verification code error"
msgstr ""

#: apps/modules/user/process/password.py:150
msgid "Password reset notification"
msgstr ""

#: apps/modules/user/process/password.py:154
#: apps/modules/user/process/sign_in.py:166
#: apps/modules/user/process/sign_up.py:107
msgid "End"
msgstr ""

#: apps/modules/user/process/password.py:161
msgid "Password reset successfully.Please return to login page to login"
msgstr ""

#: apps/modules/user/process/password.py:164
msgid "Reset password failed(unknown error)"
msgstr ""

#: apps/modules/user/process/profile.py:27
msgid "Lack of parameters \"user_id\""
msgstr ""

#: apps/modules/user/process/profile.py:63
msgid "The date of birth requires an 8-digit date,Such as '{}'"
msgstr ""

#: apps/modules/user/process/profile.py:68
#: apps/modules/user/process/sign_in.py:227
msgid "gender"
msgstr ""

#: apps/modules/user/process/profile.py:75
msgid "Address format is not in conformity with the requirements"
msgstr ""

#: apps/modules/user/process/profile.py:137
msgid "The editor saves failure"
msgstr ""

#: apps/modules/user/process/profile.py:144
#: apps/modules/user/process/sign_up.py:37
msgid "Name has been used"
msgstr ""

#: apps/modules/user/process/profile.py:147
msgid "Domain has been used"
msgstr ""

#: apps/modules/user/process/profile.py:149
msgid "Personality custom domain cannot be modified"
msgstr ""

#: apps/modules/user/process/role.py:21
msgid "The specified role is not found"
msgstr ""

#: apps/modules/user/process/role.py:71 apps/modules/user/process/role.py:126
msgid "Existing default role"
msgstr ""

#: apps/modules/user/process/role.py:79 apps/modules/user/process/role.py:133
msgid "Role name already exists"
msgstr ""

#: apps/modules/user/process/role.py:158
msgid "Delete the success, {} of the roles have users and cannot be deleted"
msgstr ""

#: apps/modules/user/process/role.py:161
msgid ""
"{} role do not have permission to delete, {} of the roles have users and "
"cannot be deleted"
msgstr ""

#: apps/modules/user/process/sign_in.py:35
#: apps/modules/user/process/sign_up.py:23
msgid "Is logged in"
msgstr ""

#: apps/modules/user/process/sign_in.py:51
#: apps/modules/user/process/sign_in.py:106
msgid "Account or password error"
msgstr ""

#: apps/modules/user/process/sign_in.py:65
#: apps/modules/user/process/sign_up.py:63
#: apps/modules/user/process/sign_up.py:82
msgid "Verification code error"
msgstr ""

#: apps/modules/user/process/sign_in.py:85
#: apps/modules/user/process/sign_in.py:205
msgid "Sign in success"
msgstr ""

#: apps/modules/user/process/sign_in.py:92
#: apps/modules/user/process/sign_in.py:209
msgid "Account is inactive or frozen"
msgstr ""

#: apps/modules/user/process/sign_in.py:147
msgid "Abnormal login"
msgstr ""

#: apps/modules/user/process/sign_in.py:157
msgid ""
"<b>Abnormal login</b><br> Your account <a>{}</a>, is logined in <span "
"style='color:#483D8B'>{}</span> on {} [UTC Time].<br>"
msgstr ""

#: apps/modules/user/process/sign_in.py:186
msgid ""
"No login processing plugin for this platform, please install the relevant"
" plugin first"
msgstr ""

#: apps/modules/user/process/sign_in.py:249
#: apps/modules/user/process/sign_up.py:119
msgid "Registered successfully"
msgstr ""

#: apps/modules/user/process/sign_in.py:253
#: apps/modules/user/process/sign_up.py:123
msgid "Data saved incorrectly, please try again"
msgstr ""

#: apps/modules/user/process/sign_up.py:43
msgid "The two passwords don't match"
msgstr ""

#: apps/modules/user/process/sign_up.py:55
msgid "This email has been registered in the site oh, please login directly."
msgstr ""

#: apps/modules/user/process/sign_up.py:73
msgid "This number has been registered in the site oh, please login directly."
msgstr ""

#: apps/modules/user/process/sign_up.py:100
msgid "Registration success notification"
msgstr ""

#: apps/modules/user/process/user.py:62
msgid "Password is not a readable attribute"
msgstr ""

#: apps/modules/user/process/user.py:127
msgid "Unknown"
msgstr ""

#: apps/modules/verification_code/process/send_code.py:35
msgid "Email"
msgstr ""

#: apps/modules/verification_code/process/send_code.py:47
#: apps/modules/verification_code/process/send_code.py:71
msgid "This account is not registered on this platform"
msgstr ""

#: apps/modules/verification_code/process/send_code.py:58
msgid "Telephone number"
msgstr ""

#: apps/modules/verification_code/process/send_code.py:109
msgid ""
"The system detects that your network is sending verification codes "
"frequently. Please try again later!"
msgstr ""

#: apps/modules/verification_code/process/send_code.py:119
msgid "Image verification code error, email not sent"
msgstr ""

#: apps/modules/verification_code/process/send_code.py:128
msgid ""
"The system detected that your operation is too frequent and you need to "
"verify the picture verification code"
msgstr ""

